Workbook

Sheet Funding Plan
A1: Seed Funding 1 | F1: Seed Funding 2 (Q6)
A3: Investor ID | B3: Value Invested | C3: Company Share (%) | D3: Cost per 0.1% Ownership | F3: Investor ID | G3: Value Invested | H3: Company Share (%) | I3: Cost per 0.1% Ownership
A4: Julian Weber (Founder) | B4: 10000 | C4: 0.34 | D4: / | F4: Julian Weber (Founder) | G4: / | H4: 0.34 | I4: /
A5: Caspar Julian Hertel (Founder) | B5: 25000 | C5: 0.17 | D5: / | F5: Caspar Julian Hertel (Founder) | G5: / | H5: 0.17 | I5: /
A6: H&W Digital Solutions | B6: 1000 | C6: 0.2 | D6: / | F6: H&W Digital Solutions | G6: / | H6: 0.18 | I6: /
A7: Paul Hannemann (Founder) | B7: 2500 | C7: 0.24 | D7: / | F7: Paul Hannemann (Founder) | G7: / | H7: 0.24 | I7: /
A8: Seed Round 1 | B8: 250000 | C8: 0.05 | D8: =(B8/(C8*100))/10 -> 5000 | F8: Seed Round 1 | G8: / | H8: 0.05 | I8: /
F9: Seed Round 2 | G9: 500000 | H9: 0.02 | I9: =(G9/(H9*100))/10 -> 25000
A12: SUM Investment | B12: =SUM(B4:B11) -> 288500 | C12: =SUM(C4:C11) -> 1 | D12: =SUM(D4:D11) -> 5000 | F12: SUM Investment | G12: =SUM(G4:G11) -> 500000 | H12: =SUM(H4:H11) -> 1 | I12: =SUM(I4:I11) -> 25000
A15: Credit Line 1 - KFW
A17: Investor ID | B17: Credit Total Value | C17: Eff. Yearly Yield (%) | D17: Total Credit Cost | E17: Monthly Credit Cost Until Y3 | F17: Monthly Credit Cost After Y3
A18: KFW | B18: 375000 | C18: 0.05 | D18: 114843.78 | E18: 0 | F18: =SUM(11718.75 / 3) -> 3906.25
A20: Gesamtsumme | B20: 375000 | C20: 114843.78 | D20: 489843.78 | E20: 0
A21: 1 | B21: 0 | C21: 1562.5 | D21: 1562.5 | E21: 375000
A22: 2 | B22: 0 | C22: 1562.5 | D22: 1562.5 | E22: 375000
A23: 3 | B23: 0 | C23: 1562.5 | D23: 1562.5 | E23: 375000
A24: 4 | B24: 0 | C24: 1562.5 | D24: 1562.5 | E24: 375000
A25: 5 | B25: 0 | C25: 1562.5 | D25: 1562.5 | E25: 375000
A26: 6 | B26: 0 | C26: 1562.5 | D26: 1562.5 | E26: 375000
A27: 7 | B27: 0 | C27: 1562.5 | D27: 1562.5 | E27: 375000
A28: 8 | B28: 0 | C28: 1562.5 | D28: 1562.5 | E28: 375000
A29: 9 | B29: 0 | C29: 1562.5 | D29: 1562.5 | E29: 375000
A30: 10 | B30: 0 | C30: 1562.5 | D30: 1562.5 | E30: 375000
A31: 11 | B31: 0 | C31: 1562.5 | D31: 1562.5 | E31: 375000
A32: 12 | B32: 0 | C32: 1562.5 | D32: 1562.5 | E32: 375000
... A140: 120 | B140: 11718.75 | C140: 48.83 | D140: 11767.58 | E140: 0

Sheet Employee Plan
B1: Year 1
A3: Personal Y1-Q1(kumulativ) | C3: 26Q3 | E3: Contractors Y1-Q1(kumulativ) | G3: 26Q3
A4: Role | B4: Employees | C4: Cost | E4: Role | F4: FTE | G4: Cost
A5: Developer (Backend) | B5: 1 | C5: =B5*('Role-Salary Helper '!C13*'Role-Salary Helper '!C27*51) -> 7956 | E5: AI & Architecture Specialist | F5: 0.3 | G5: =F5*(51*'Role-Salary Helper '!F16) -> 5355
A6: Developer (Frontend) | B6: 1 | C6: =B6*('Role-Salary Helper '!C14*'Role-Salary Helper '!C27*51) -> 6961.5 | E6: Ad & Content Creator | F6: 0.3 | G6: =F6*(51*'Role-Salary Helper '!F17) -> 2295
A7: UX/UI Designer | B7: 1 | C7: =B7*('Role-Salary Helper '!C15*'Role-Salary Helper '!C27*51) -> 6630 | E7: Legal | F7: 0.025 | G7: =F7*(51*'Role-Salary Helper '!F19) -> 765
A8: CTO + CEO | B8: 1 | C8: =B8*('Role-Salary Helper '!F27*51) -> 17850 | E8: Digital Marketing | F8: 0.3 | G8: =F8*('Role-Salary Helper '!F21*51) -> 2295
A9: CEO + CFO | B9: 0.3 | C9: =B9*('Role-Salary Helper '!F27*51) -> 5355 | G9: =F9*(102*250) -> 0
A10: CMO | B10: 0.1 | C10: =B10*('Role-Salary Helper '!F27*51) -> 1785 | G10: =F10*(102*250) -> 0
C11: =B11*(36400/4) -> 0 | G11: =F11*(102*250) -> 0
C12: =B12*(102*250) -> 0 | G12: =F12*(102*250) -> 0
A13: TOTAL | B13: =SUM(B5:B12) -> 4.4 | C13: =SUM(C5:C12) -> 46537.5 | E13: TOTAL | F13: =SUM(F5:F12) -> 0.925 | G13: =SUM(G5:G12) -> 10710
C15: Quarter Total Cost | I15: Y1 Cost (Cumulating)
C16: =SUM(G13,C13) -> 57247.5 | I16: =SUM(C16) -> 57247.5
A19: Personal Y1-Q2 (kumulativ) | C19: 26Q4 | E19: Contractors Y1-Q2 (kumulativ) | G19: 26Q4
A20: Role | B20: Employees | C20: Cost | E20: Role | F20: FTE | G20: Cost
A21: QA & Testing | B21: 1 | C21: =B21*('Role-Salary Helper '!C12*'Role-Salary Helper '!C28*51) -> 4845 | E21: AI & Architecture Specialist | F21: 0.2 | G21: =F21*(51*'Role-Salary Helper '!F16) -> 3570
A22: Developer (Backend) | B22: 1 | C22: =B22*('Role-Salary Helper '!C13*'Role-Salary Helper '!C27*51) -> 7956 | E22: Ad & Content Creator | F22: 0.1 | G22: =F22*(51*'Role-Salary Helper '!F17) -> 765
A23: Developer (Frontend) | B23: 1 | C23: =B23*('Role-Salary Helper '!C14*'Role-Salary Helper '!C27*51) -> 6961.5 | E23: Legal | F23: 0.025 | G23: =F23*(51*'Role-Salary Helper '!F19) -> 765
A24: UX/UI Designer | B24: 1 | C24: =B24*('Role-Salary Helper '!C15*'Role-Salary Helper '!C27*51) -> 6630 | E24: Digital Marketing | F24: 0.3 | G24: =F24*('Role-Salary Helper '!F21*51) -> 2295
A25: CTO + CEO | B25: 1 | C25: =B25*('Role-Salary Helper '!F27*51) -> 17850 | G25: =F25*(102*250) -> 0
A26: CEO + CFO | B26: 0.3 | C26: =B26*('Role-Salary Helper '!F27*51) -> 5355 | G26: =F26*(102*250) -> 0
A27: CMO | B27: 0.1 | C27: =B27*('Role-Salary Helper '!F27*51) -> 1785 | G27: =F27*(102*250) -> 0
C28: =B28*(102*250) -> 0 | G28: =F28*(102*250) -> 0
A29: TOTAL | B29: =SUM(B21:B28) -> 5.4 | C29: =SUM(C21:C28) -> 51382.5 | E29: TOTAL | F29: =SUM(F21:F28) -> 0.625 | G29: =SUM(G21:G28) -> 7395
C31: Quarter Total Cost | I31: Y1 Cost (Cumulating)
C32: =SUM(C29,G29) -> 58777.5 | I32: =SUM(I16,C32) -> 116025
A36: Personal Y1-Q3(kumulativ) | C36: 27Q1 | E36: Contractors Y1-Q3(kumulativ) | G36: 27Q1
A37: Role | B37: Employees | C37: Cost | E37: Role | F37: FTE | G37: Cost
A38: QA & Testing | B38: 1 | C38: =B38*('Role-Salary Helper '!C12*'Role-Salary Helper '!C28*51) -> 4845 | E38: AI & Architecture Specialist | F38: 0.3 | G38: =F38*('Role-Salary Helper '!F16*51) -> 5355
A39: Developer (Backend) | B39: 1 | C39: =B39*('Role-Salary Helper '!C13*'Role-Salary Helper '!C27*51) -> 7956 | E39: Ad & Content Creator | F39: 0.3 | G39: =F39*('Role-Salary Helper '!F17*51) -> 2295
A40: Developer (Frontend) | B40: 1 | C40: =B40*('Role-Salary Helper '!C14*'Role-Salary Helper '!C27*51) -> 6961.5 | E40: Legal | F40: 0.025 | G40: =F40*('Role-Salary Helper '!F19*51) -> 765
A41: UX/UI Designer | B41: 1 | C41: =B41*('Role-Salary Helper '!C15*'Role-Salary Helper '!C27*51) -> 6630 | E41: Digital Marketing | F41: 0.3 | G41: =F41*('Role-Salary Helper '!F21*51) -> 2295
A42: CTO + CEO | B42: 1 | C42: =B42*('Role-Salary Helper '!F27*51) -> 17850
A43: CEO + CFO | B43: 0.3 | C43: =B43*('Role-Salary Helper '!F27*51) -> 5355
A44: CMO | B44: 0.1 | C44: =B44*('Role-Salary Helper '!F27*51) -> 1785 | G44: 0
C45: 0 | G45: 0
A46: TOTAL | B46: =SUM(B38:B45) -> 5.4 | C46: =SUM(C38:C45) -> 51382.5 | E46: TOTAL | F46: =SUM(F38:F45) -> 0.925 | G46: =SUM(G38:G45) -> 10710
C48: Quarter Total Cost | I48: Y1Cost (Cumulating)
C49: =SUM(C46,G46) -> 62092.5 | I49: =SUM(I32,C49) -> 178117.5
...

Sheet Role-Salary Helper 
B9: INTERNAL EMPLOYEES (Remote ) | E9: CONTRACTORS TBD!!!
B11: Role | C11: Cost per FTE | E11: Role | F11: Cost per FTE
B12: QA & Testing | C12: 190 | E12: QA & Testing | F12: 190
B13: Developer (Backend) | C13: 240 | E13: Sr. Developer (Backend) | F13: 280
B14: Developer (Frontend) | C14: 210 | E14: Developer (Frontend) | F14: 220
B15: UX/UI Designer | C15: 200 | E15: UX/UI Designer | F15: 200
B16: Digital Marketing | C16: 220 | E16: AI & Architecture Specialist | F16: 350
B17: Key Account Manager | C17: 235 | E17: Ad & Contend Creator | F17: 150
B18: Sales Development Rep. | C18: 180 | E18: DevOps | F18: 300
B19: DevOps | C19: 300 | E19: Legal | F19: 600
E20: Sales Dev. Rep. | F20: 144
E21: Digital Marketing | F21: 150
B24: INTERNAL EMPLOYEES (Remote Outsourced ) | E24: C-Suite
B26: Role | C26: Cost per FTE | E26: Role | F26: Cost per FTE
B27: Poland | C27: =0.65 -> 0.65 | E27: C-Suite | F27: 350
B28: Romania | C28: =0.5 -> 0.5 | E28: C-Suite Full-Time | F28: 350

Sheet Fixed Cost
A1: Financial Planning
A3: Licensing & other Fees
A5: Software Licenses | E5: Assets
A7: Software | B7: Monthly Cost | E7: Asset | F7: Monthly Cost
A8: Microsoft 365 Enterprise | B8: =8*SUM('OLD Employee & Contracting Cost'!B13) -> 58 | E8: Office Space incl. WiFi | F8: 820
A9: Cursor | B9: 200 | E9: Office Refreshments | F9: 50
A10: Hetzner AI GPU Test Server | B10: 500 | E10: Advertising | F10: 2500
A11: ChatGPT Team License | B11: 150 | E11: Other | F11: 200
A12: VPN Licenses | B12: 150
A13: Internal Server Cost | B13: 250
A14: Other | B14: 200
A15: Total | B15: =SUM(B8:B14) -> 1508 | E15: Total | F15: =SUM(F8:F13) -> 3570
A20: Total Monthly Cost | B20: =B15+F15 -> 5078
A21: Total Yearly Cost | B21: =B20*12 -> 60936

Sheet Earning Projections
A1: Financial Planning
A3: Earning Projections
A5: Assumption: Project Launch in Q3 2026 with Investment Plan A
A7: Pricing Structure | I7: Sales Forecast per Quarter
C8: <50 | D8: 50-750 | E8: 750+ | F8: Employee Reference*
C9: Small Company | D9: Medium Company | E9: Large Company | I9: Quarter | J9: Basic-Small | K9: Basic-Medium | L9: Basic-Large | M9: Pro-Small | N9: Pro-Medium | O9: Pro-Large | P9: Ent-Small | Q9: Ent-Medium | R9: Ent-Large | T9: All | U9: Small | V9: Medium | W9: Large
A10: Basic - Setup Fee | C10: 4000 | D10: 8000 | E10: 8000 | H10: MVP1 Completion | I10: Q1 2027 | J10: 2 | K10: 0 | L10: 0 | M10: 0 | N10: 0 | O10: 0 | P10: 0 | Q10: 0 | R10: 0 | T10: =SUM(J10:R10) -> 2 | U10: =J10+M10+P10 -> 2 | V10: =K10+N10+Q10 -> 0 | W10: =L10+O10+R10 -> 0
A11: Basic - Monthly License | C11: 600 | D11: 1000 | E11: 4000 | H11: MVP2 Completion | I11: Q2 2027 | J11: 3 | K11: 1 | L11: 0 | M11: 0 | N11: 1 | O11: 0 | P11: 0 | Q11: 0 | R11: 0 | T11: =SUM(J11:R11) -> 5 | U11: =J11+M11+P11 -> 3 | V11: =K11+N11+Q11 -> 2 | W11: =L11+O11+R11 -> 0
A12: Pro - Setup Fee | C12: 6000 | D12: 12000 | E12: 12000 | I12: Q3 2027 | J12: 4 | K12: 2 | L12: 0 | M12: 0 | N12: 1 | O12: 0 | P12: 0 | Q12: 0 | R12: 0 | T12: =SUM(J12:R12) -> 7 | U12: =J12+M12+P12 -> 4 | V12: =K12+N12+Q12 -> 3 | W12: =L12+O12+R12 -> 0
A13: Pro - Monthly License | C13: 1000 | D13: 2500 | E13: 5000 | H13: MVP3 Completion | I13: Q4 2027 | J13: 5 | K13: 3 | L13: 0 | M13: 0 | N13: 2 | O13: 0 | P13: 0 | Q13: 0 | R13: 0 | T13: =SUM(J13:R13) -> 10 | U13: =J13+M13+P13 -> 5 | V13: =K13+N13+Q13 -> 5 | W13: =L13+O13+R13 -> 0
A14: Enterprise - Setup Fee | C14: 10000 | D14: 20000 | E14: 20000 | I14: Q1 2028 | J14: 7 | K14: 5 | L14: 0 | M14: 1 | N14: 4 | O14: 0 | P14: 0 | Q14: 1 | R14: 0 | T14: =SUM(J14:R14) -> 18 | U14: =J14+M14+P14 -> 8 | V14: =K14+N14+Q14 -> 10 | W14: =L14+O14+R14 -> 0
A15: Enterprise - Monthly License | C15: 1500 | D15: 4000 | E15: 7500 | I15: Q2 2028 | J15: 9 | K15: 7 | L15: 0 | M15: 2 | N15: 7 | O15: 0 | P15: 0 | Q15: 3 | R15: 1 | T15: =SUM(J15:R15) -> 29 | U15: =J15+M15+P15 -> 11 | V15: =K15+N15+Q15 -> 17 | W15: =L15+O15+R15 -> 1
A16: Cost per Customer | C16: 220 | D16: 300 | E16: 800 | I16: Q3 2028 | J16: 14 | K16: 9 | L16: 0 | M16: 4 | N16: 10 | O16: 1 | P16: 1 | Q16: 5 | R16: 2 | T16: =SUM(J16:R16) -> 46 | U16: =J16+M16+P16 -> 19 | V16: =K16+N16+Q16 -> 24 | W16: =L16+O16+R16 -> 3
I17: Q4 2028 | J17: 16 | K17: 11 | L17: 0 | M17: 6 | N17: 12 | O17: 2 | P17: 2 | Q17: 8 | R17: 3 | T17: =SUM(J17:R17) -> 60 | U17: =J17+M17+P17 -> 24 | V17: =K17+N17+Q17 -> 31 | W17: =L17+O17+R17 -> 5
I18: Q1 2029 | J18: 22 | K18: 15 | L18: 0 | M18: 10 | N18: 16 | O18: 4 | P18: 4 | Q18: 13 | R18: 4 | T18: =SUM(J18:R18) -> 88 | U18: =J18+M18+P18 -> 36 | V18: =K18+N18+Q18 -> 44 | W18: =L18+O18+R18 -> 8
I19: Q2 2029 | J19: 27 | K19: 18 | L19: 2 | M19: 11 | N19: 19 | O19: 5 | P19: 4 | Q19: 19 | R19: 7 | T19: =SUM(J19:R19) -> 112 | U19: =J19+M19+P19 -> 42 | V19: =K19+N19+Q19 -> 56 | W19: =L19+O19+R19 -> 14
A20: Earnings Projections | I20: Totals Q2 2029 | J20: =SUM(J10:J19) -> 109 | K20: =SUM(K10:K19) -> 71 | L20: =SUM(L10:L19) -> 2 | M20: =SUM(M10:M19) -> 34 | N20: =SUM(N10:N19) -> 72 | O20: =SUM(O10:O19) -> 12 | P20: =SUM(P10:P19) -> 11 | Q20: =SUM(Q10:Q19) -> 49 | R20: =SUM(R10:R19) -> 17 | T20: =SUM(J20:R20) -> 377 | U20: =J20+M20+P20 -> 154 | V20: =K20+N20+Q20 -> 192 | W20: =L20+O20+R20 -> 31
A22: Quarter | B22: Setup Revenue | C22: Recurring Revenue | D22: Total Revenue | E22: Related Cost | F22: Cumulative Cost | G22: Total Profit
A23: Q1 2027 | B23: =J10*C10+K10*D10+L10*E10+M10*C12+N10*D12+O10*E12+P10*C14+Q10*D14+R10*E14 -> 8000 | C23: =(J10*C11+K10*D11+L10*E11+M10*C13+N10*D13+O10*E13+P10*C15+Q10*D15+R10*E15)*3 -> 3600 | D23: =SUM(B23:C23) -> 11600 | E23: =(((J10+M10+P10)*C16)+((K10+N10+Q10)*D16)+((L10+O10+R10)*E16)) -> 440 | F23: =E23 -> 440 | G23: =D23-F23 -> 11160
A24: Q2 2027 | B24: =J11*C10+K11*D10+L11*E10+M11*C12+N11*D12+O11*E12+P11*C14+Q11*D14+R11*E14 -> 32000 | C24: =((J11*C11+K11*D11+L11*E11+M11*C13+N11*D13+O11*E13+P11*C15+Q11*D15+R11*E15)*3)+C23 -> 19500 | D24: =SUM(B24:C24) -> 51500 | E24: =(((J11+M11+P11)*C16)+((K11+N11+Q11)*D16)+((L11+O11+R11)*E16)) -> 1260 | F24: =E24+F23 -> 1700 | G24: =D24-F24 -> 49800
A25: Q3 2027 | B25: =J12*C10+K12*D10+L12*E10+M12*C12+N12*D12+O12*E12+P12*C14+Q12*D14+R12*E14 -> 44000 | C25: =((J12*C11+K12*D11+L12*E11+M12*C13+N12*D13+O12*E13+P12*C15+Q12*D15+R12*E15)*3)+C24 -> 40200 | D25: =SUM(B25:C25) -> 84200 | E25: =(((J12+M12+P12)*C16)+((K12+N12+Q12)*D16)+((L12+O12+R12)*E16)) -> 1780 | F25: =E25+F24 -> 3480 | G25: =D25-F25 -> 80720
A26: Q4 2027 | B26: =J13*C10+K13*D10+L13*E10+M13*C12+N13*D12+O13*E12+P13*C14+Q13*D14+R13*E14 -> 68000 | C26: =((J13*C11+K13*D11+L13*E11+M13*C13+N13*D13+O13*E13+P13*C15+Q13*D15+R13*E15)*3)+C25 -> 73200 | D26: =SUM(B26:C26) -> 141200 | E26: =(((J13+M13+P13)*C16)+((K13+N13+Q13)*D16)+((L13+O13+R13)*E16)) -> 2600 | F26: =E26+F25 -> 6080 | G26: =D26-F26 -> 135120 | H26: 2027 License Revenue: | I26: =SUM(D23:D26) -> 288500
A27: Q1 2028 | B27: =J14*C10+K14*D10+L14*E10+M14*C12+N14*D12+O14*E12+P14*C14+Q14*D14+R14*E14 -> 142000 | C27: =((J14*C11+K14*D11+L14*E11+M14*C13+N14*D13+O14*E13+P14*C15+Q14*D15+R14*E15)*3)+C26 -> 145800 | D27: =SUM(B27:C27) -> 287800 | E27: =(((J14+M14+P14)*C16)+((K14+N14+Q14)*D16)+((L14+O14+R14)*E16)) -> 4760 | F27: =E27+F26 -> 10840 | G27: =D27-F27 -> 276960 | H27: 2027 License Profit: | I27: =SUM(G23:G26) -> 276800
A28: Q2 2028 | B28: =J15*C10+K15*D10+L15*E10+M15*C12+N15*D12+O15*E12+P15*C14+Q15*D14+R15*E14 -> 268000 | C28: =((J15*C11+K15*D11+L15*E11+M15*C13+N15*D13+O15*E13+P15*C15+Q15*D15+R15*E15)*3)+C27 -> 300000 | D28: =SUM(B28:C28) -> 568000 | E28: =(((J15+M15+P15)*C16)+((K15+N15+Q15)*D16)+((L15+O15+R15)*E16)) -> 8320 | F28: =E28+F27 -> 19160 | G28: =D28-F28 -> 548840
A29: Q3 2028 | B29: =J16*C10+K16*D10+L16*E10+M16*C12+N16*D12+O16*E12+P16*C14+Q16*D14+R16*E14 -> 434000 | C29: =((J16*C11+K16*D11+L16*E11+M16*C13+N16*D13+O16*E13+P16*C15+Q16*D15+R16*E15)*3)+C28 -> 563700 | D29: =SUM(B29:C29) -> 997700 | E29: =(((J16+M16+P16)*C16)+((K16+N16+Q16)*D16)+((L16+O16+R16)*E16)) -> 13780 | F29: =E29+F28 -> 32940 | G29: =D29-F29 -> 964760
A30: Q4 2028 | B30: =J17*C10+K17*D10+L17*E10+M17*C12+N17*D12+O17*E12+P17*C14+Q17*D14+R17*E14 -> 596000 | C30: =((J17*C11+K17*D11+L17*E11+M17*C13+N17*D13+O17*E13+P17*C15+Q17*D15+R17*E15)*3)+C29 -> 936000 | D30: =SUM(B30:C30) -> 1532000 | E30: =(((J17+M17+P17)*C16)+((K17+N17+Q17)*D16)+((L17+O17+R17)*E16)) -> 18580 | F30: =E30+F29 -> 51520 | G30: =D30-F30 -> 1480480 | H30: 2028 License Revenue: | I30: =SUM(D27:D30) -> 3385500
A31: Q1 2029 | B31: =J18*C10+K18*D10+L18*E10+M18*C12+N18*D12+O18*E12+P18*C14+Q18*D14+R18*E14 -> 888000 | C31: =((J18*C11+K18*D11+L18*E11+M18*C13+N18*D13+O18*E13+P18*C15+Q18*D15+R18*E15)*3)+C30 -> 1494600 | D31: =SUM(B31:C31) -> 2382600 | E31: =(((J18+M18+P18)*C16)+((K18+N18+Q18)*D16)+((L18+O18+R18)*E16)) -> 27520 | F31: =E31+F30 -> 79040 | G31: =D31-F31 -> 2303560 | H31: 2028 License Profit: | I31: =SUM(G27:G30) -> 3271040
A32: Q2 2029 | B32: =J19*C10+K19*D10+L19*E10+M19*C12+N19*D12+O19*E12+P19*C14+Q19*D14+R19*E14 -> 1182000 | C32: =((J19*C11+K19*D11+L19*E11+M19*C13+N19*D13+O19*E13+P19*C15+Q19*D15+R19*E15)*3)+C31 -> 2275200 | D32: =SUM(B32:C32) -> 3457200 | E32: =(((J19+M19+P19)*C16)+((K19+N19+Q19)*D16)+((L19+O19+R19)*E16)) -> 37240 | F32: =E32+F31 -> 116280 | G32: =D32-F32 -> 3340920

Sheet Marketing

Sheet Cost & Burn Calculation
A1: Quarter | B1: Quarter Total Employee Cost | C1: Quarter Total Fixed Cost | D1: Quarter Total Credit Cost | E1: Quarter Total License Cost | F1: Quarter Total Cost
A2: 1 | B2: ='Employee Plan'!C16 -> 57247.5 | C2: ='Fixed Cost'!B20 * 3 -> 15234 | D2: 0 | E2: 0 | F2: =SUM(B2:E2) -> 72481.5
A3: 2 | B3: ='Employee Plan'!C32 -> 58777.5 | C3: ='Fixed Cost'!B20 * 3 -> 15234 | D3: 0 | E3: 0 | F3: =SUM(B3:E3) -> 74011.5
A4: 3 | B4: ='Employee Plan'!C49 -> 62092.5 | C4: ='Fixed Cost'!B20 * 3 -> 15234 | D4: 0 | E4: ='Earning Projections'!E23 -> 440 | F4: =SUM(B4:E4) -> 77766.5
A5: 4 | B5: ='Employee Plan'!C66 -> 63622.5 | C5: ='Fixed Cost'!B20 * 3 -> 15234 | D5: 0 | E5: ='Earning Projections'!E24 -> 1260 | F5: =SUM(B5:E5) -> 80116.5
A6: 5 | B6: ='Employee Plan'!C88 -> 85705.5 | C6: ='Fixed Cost'!B20 * 3 -> 15234 | D6: 0 | E6: ='Earning Projections'!E25 -> 1780 | F6: =SUM(B6:E6) -> 102719.5
A7: 6 | B7: ='Employee Plan'!C88 -> 85705.5 | C7: ='Fixed Cost'!B20 * 3 -> 15234 | D7: 0 | E7: ='Earning Projections'!E26 -> 2600 | F7: =SUM(B7:E7) -> 103539.5
A8: 7 | B8: ='Employee Plan'!C125 -> 94885.5 | C8: ='Fixed Cost'!B20 * 3 -> 15234 | D8: 0 | E8: ='Earning Projections'!E27 -> 4760 | F8: =SUM(B8:E8) -> 114879.5
A9: 8 | B9: ='Employee Plan'!C125 -> 94885.5 | C9: ='Fixed Cost'!B20 * 3 -> 15234 | D9: 0 | E9: ='Earning Projections'!E28 -> 8320 | F9: =SUM(B9:E9) -> 118439.5
A10: 9 | C10: ='Fixed Cost'!B28 -> 0 | D10: 0 | E10: ='Earning Projections'!E29 -> 13780 | F10: =SUM(B10:E10) -> 13780
A11: 10 | C11: ='Fixed Cost'!B29 -> 0 | D11: 0 | E11: ='Earning Projections'!E30 -> 18580 | F11: =SUM(B11:E11) -> 18580
A12: 11 | C12: ='Fixed Cost'!B30 -> 0 | D12: 0 | E12: ='Earning Projections'!E31 -> 27520 | F12: =SUM(B12:E12) -> 27520
A13: 12 | C13: ='Fixed Cost'!B31 -> 0 | D13: 0 | E13: ='Earning Projections'!E32 -> 37240 | F13: =SUM(B13:E13) -> 37240
A14: TOTAL | B14: =SUM(B2:B13) -> 602922 | C14: =SUM(C2:C13) -> 121872 | D14: =SUM(D2:D13) -> 0 | E14: =SUM(E2:E13) -> 116280 | F14: =SUM(F2:F13) -> 841074
A16: Quarter | B16: Quarter Total License Revenue | C16: Quarter Total Setup Revenue | D16: Quarter Total Client Revenue | E16: Quarter Total Result
A17: 1 | B17: 0 | C17: 0 | D17: ='Fixed Cost'!C35 * 3 -> 0 | E17: =D17-D2 -> 0
A18: 2 | B18: 0 | C18: 0 | D18: ='Fixed Cost'!C35 * 3 -> 0 | E18: =D18-D3 -> 0
A19: 3 | B19: ='Earning Projections'!C23 -> 3600 | C19: ='Earning Projections'!B23 -> 8000 | D19: =SUM(B19,C19) -> 11600 | E19: =D19-D4 -> 11600
A20: 4 | B20: ='Earning Projections'!C24 -> 19500 | C20: ='Earning Projections'!B24 -> 32000 | D20: =SUM(B20,C20) -> 51500 | E20: =D20-D5 -> 51500
A21: 5 | B21: ='Earning Projections'!C25 -> 40200 | C21: ='Earning Projections'!B25 -> 44000 | D21: =SUM(B21,C21) -> 84200 | E21: =D21-D6 -> 84200
A22: 6 | B22: ='Earning Projections'!C26 -> 73200 | C22: ='Earning Projections'!B26 -> 68000 | D22: =SUM(B22,C22) -> 141200 | E22: =D22-D7 -> 141200
A23: 7 | B23: ='Earning Projections'!C27 -> 145800 | C23: ='Earning Projections'!B27 -> 142000 | D23: =SUM(B23,C23) -> 287800 | E23: =D23-D8 -> 287800
A24: 8 | B24: ='Earning Projections'!C28 -> 300000 | C24: ='Earning Projections'!B28 -> 268000 | D24: =SUM(B24,C24) -> 568000 | E24: =D24-D9 -> 568000
A25: 9 | B25: ='Earning Projections'!C29 -> 563700 | C25: ='Earning Projections'!B29 -> 434000 | D25: =SUM(B25,C25) -> 997700 | E25: =D25-D10 -> 997700
A26: 10 | B26: ='Earning Projections'!C30 -> 936000 | C26: ='Earning Projections'!B30 -> 596000 | D26: =SUM(B26,C26) -> 1532000 | E26: =D26-D11 -> 1532000
A27: 11 | B27: ='Earning Projections'!C31 -> 1494600 | C27: ='Earning Projections'!B31 -> 888000 | D27: =SUM(B27,C27) -> 2382600 | E27: =D27-D12 -> 2382600
A28: 12 | B28: ='Earning Projections'!C32 -> 2275200 | C28: ='Earning Projections'!B32 -> 1182000 | D28: =SUM(B28,C28) -> 3457200 | E28: =D28-D13 -> 3457200
A29: TOTAL | B29: =SUM(B17:B28) -> 5851800 | C29: =SUM(C17:C28) -> 3662000 | D29: =SUM(D17:D28) -> 9513800 | E29: =SUM(E17:E28) -> 9513800
C31: Pessimistic Scenario: | D31: Quarter Total Client Revenue | E31: Quarter Total Result
D32: 0 | E32: =D32-F2 -> -72481.5
C33: !!! For the Pessimistic Scenario Sales will be only | D33: 0 | E33: =D33-F3 -> -74011.5
C34: 0.1 | D34: 0 | E34: =D34-F4 -> -77766.5
C35: … of the currently projected Sales!!! | D35: 0 | E35: =D35-F5 -> -80116.5
D36: 0 | E36: =D36-F6 -> -102719.5
D37: 0 | E37: =D37-F7 -> -103539.5
D38: =SUM(D23,E8)*C34 -> 29256 | E38: =D38-F8 -> -85623.5
D39: =SUM(D24,E9)*C34 -> 57632 | E39: =D39-F9 -> -60807.5
C40: s | D40: =SUM(D25,E10)*C34 -> 101148 | E40: =D40-F10 -> 87368
D41: =SUM(D26,E11)*C34 -> 155058 | E41: =D41-F11 -> 136478
D42: =SUM(D27,E12)*C34 -> 241012 | E42: =D42-F12 -> 213492
...

Sheet initial Dev Cost
A1: Financial Planning
A3: Development Cost Breakdown
A5: Investment Plan A | F5: Investment Plan B | K5: Investment Plan C | Q5: Investment Plan D
Q6: Board members take over Tier 2 tasks during initial 6 month scaling phase
A7: Dev Team Setup | F7: Dev Team Setup | K7: Dev Team Setup | Q7: Dev Team Setup
A8: Role | B8: FTE | F8: Role | G8: FTE | K8: Role | L8: FTE | Q8: Role | R8: FTE
A9: Tech Lead | B9: 1 | F9: Tech Lead | G9: 1 | K9: Tech Lead | L9: 1 | Q9: Tech Lead | R9: 0
A10: Developer | B10: 3 | F10: Developer | G10: 5 | K10: Developer | L10: 2 | Q10: Developer | R10: 3
A11: QA | B11: 1 | F11: QA | G11: 2 | K11: QA | L11: 0.5 | Q11: QA | R11: 1
A12: DevOps | B12: 0.25 | F12: DevOps | G12: 0.5 | K12: DevOps | L12: 0.15 | Q12: DevOps | R12: 0.25
A13: UX/UI Designer | B13: 0.5 | F13: UX/UI Designer | G13: 1 | K13: UX/UI Designer | L13: 0.25 | Q13: UX/UI Designer | R13: 0.5
A14: Architecture | B14: 0.2 | F14: Architecture | G14: 0.4 | K14: Architecture | L14: 0.1 | Q14: Architecture | R14: 0
A15: Product Management | B15: 0.5 | F15: Product Management | G15: 1 | K15: Product Management | L15: 0.25 | Q15: Product Management | R15: 0
A16: Project Management | B16: 0.25 | F16: Project Management | G16: 0.5 | K16: Project Management | L16: 0.2 | Q16: Project Management | R16: 0
A17: Sum Tier 1 | B17: =B10+B11+B12+B13 -> 4.75 | F17: Sum Tier 1 | G17: =G10+G11+G12+G13 -> 8.5 | K17: Sum Tier 1 | L17: =L10+L11+L12+L13 -> 2.9 | Q17: Sum Tier 1 | R17: =R10+R11+R12+R13 -> 4.75
A18: Sum Tier 2 | B18: =B9+B14+B15+B16 -> 1.95 | F18: Sum Tier 2 | G18: =G9+G14+G15+G16 -> 2.9 | K18: Sum Tier 2 | L18: =L9+L14+L15+L16 -> 1.55 | Q18: Sum Tier 2 | R18: =R9+R14+R15+R16 -> 0
A20: Daily Rates: | F20: Daily Rates: | K20: Daily Rates: | Q20: Daily Rates:
A21: Tier 1 | B21: 200 | F21: Tier 1 | G21: 200 | K21: Tier 1 | L21: 200 | Q21: Tier 1 | R21: 200
A22: Tier 2 | B22: 400 | F22: Tier 2 | G22: 400 | K22: Tier 2 | L22: 400 | Q22: Tier 2 | R22: 400
A24: Feature Estimation Plan A | F24: Feature Estimation Plan B | K24: Feature Estimation Plan C | Q24: Feature Estimation Plan D
A25: Feature | D25: Duration in Months | F25: Feature | I25: Duration in Months | K25: Feature | N25: Duration in Months | Q25: Feature | T25: Duration in Months
A27: AI SOC Triage Analysis + Reports | D27: 3 | F27: AI SOC Triage Analysis + Reports | I27: 2 | K27: AI SOC Triage Analysis + Reports | N27: 5 | Q27: AI SOC Triage Analysis + Reports | T27: 3
A28: SOC Responder AI Agent | D28: 2 | F28: SOC Responder AI Agent | I28: 1.5 | K28: SOC Responder AI Agent | N28: 4 | Q28: SOC Responder AI Agent | T28: 2
A29: IT Assetmanagement incl. Audit Trail | D29: 2 | F29: IT Assetmanagement incl. Audit Trail | I29: 1.5 | K29: IT Assetmanagement incl. Audit Trail | N29: 4 | Q29: IT Assetmanagement incl. Audit Trail | T29: 2
A30: Knowledgebase Module Extension | D30: 3 | F30: Knowledgebase Module Extension | I30: 2 | K30: Knowledgebase Module Extension | N30: 5 | Q30: Knowledgebase Module Extension | T30: 3
A31: Active Hunting AI Agent | D31: 2 | F31: Change- & Releasemanagement Module | I31: 1.5 | K31: Change- & Releasemanagement Module | N31: 4 | Q31: Active Hunting AI Agent | T31: 2
A32: MVP 1 Total | D32: =D27 -> 3 | F32: MVP 1 Total | I32: =I27 -> 2 | K32: MVP 1 Total | N32: =N27 -> 5 | Q32: MVP 1 Total | T32: =T27 -> 3
A33: MVP 2 Total | D33: =D27+D28 -> 5 | F33: MVP 2 Total | I33: =I27+I28 -> 3.5 | K33: MVP 2 Total | N33: =N27+N28 -> 9 | Q33: MVP 2 Total | T33: =T27+T28 -> 5
A34: MVP 3 Total | D34: =D27+D28+D29+D30+D31 -> 12 | F34: MVP 3 Total | I34: =I27+I28+I29+I30+I31 -> 8.5 | K34: MVP 3 Total | N34: =N27+N28+N29+N30+N31 -> 22 | Q34: MVP 3 Total | T34: =T27+T28+T29+T30+T31 -> 12
A37: Bottom Line Plan A | F37: Bottom Line Plan B | K37: Bottom Line Plan C | Q37: Bottom Line Plan D
A39: Scope | B39: Total Duration | D39: Total Cost | F39: Scope | G39: Total Duration | I39: Total Cost | K39: Scope | L39: Total Duration | N39: Total Cost | Q39: Scope | R39: Total Duration | T39: Total Cost
A40: MVP 1 | B40: =D32 -> 3 | D40: =ROUND((17*B40*B17*B21)+(17*B40*B18*B22), -4) -> 90000 | F40: MVP 1 | G40: =I32 -> 2 | I40: =ROUND((17*G40*G17*G21)+(17*G40*G18*G22), -4) -> 100000 | K40: MVP 1 | L40: =N32 -> 5 | N40: =ROUND((17*L40*L17*L21)+(17*L40*L18*L22), -4) -> 100000 | Q40: MVP 1 | R40: =T32 -> 3 | T40: =ROUND((17*R40*R17*R21)+(17*R40*R18*R22), -4) -> 50000
A41: MVP 2 | B41: =D33 -> 5 | D41: =ROUND((17*B41*B17*B21)+(17*B41*B18*B22), -4) -> 150000 | F41: MVP 2 | G41: =I33 -> 3.5 | I41: =ROUND((17*G41*G17*G21)+(17*G41*G18*G22), -4) -> 170000 | K41: MVP 2 | L41: =N33 -> 9 | N41: =ROUND((17*L41*L17*L21)+(17*L41*L18*L22), -4) -> 180000 | Q41: MVP 2 | R41: =T33 -> 5 | T41: =ROUND((17*R41*R17*R21)+(17*R41*R18*R22), -4) -> 80000
A42: MVP 3 | B42: =D34 -> 12 | D42: =ROUND((17*B42*B17*B21)+(17*B42*B18*B22), -4) -> 350000 | F42: MVP 3 | G42: =I34 -> 8.5 | I42: =ROUND((17*G42*G17*G21)+(17*G42*G18*G22), -4) -> 410000 | K42: MVP 3 | L42: =N34 -> 22 | N42: =ROUND((17*L42*L17*L21)+(17*L42*L18*L22), -4) -> 450000 | Q42: MVP 3 | R42: =T34 -> 12 | T42: =ROUND((17*R42*R17*R21)+(17*R42*R18*R22), -4) -> 190000
A44: Quarterly Cost of Development | D44: =ROUND((17*3*B17*B21)+(17*3*B18*B22), -4) -> 90000 | F44: Quarterly Cost of Development | I44: =ROUND((17*3*G17*G21)+(17*3*G18*G22), -4) -> 150000 | K44: Quarterly Cost of Development | N44: =ROUND((17*3*L17*L21)+(17*3*L18*L22), -4) -> 60000 | Q44: Quarterly Cost of Development | T44: =ROUND((17*3*R17*R21)+(17*3*R18*R22), -4) -> 50000

Sheet OLD Employee & Contracting Cost
A3: Personal Y1-Q1-Q2 (kumulativ) | C3: 26Q3-Q4 | E3: Contractors Y1-Q1-Q2 (kumulativ) | G3: 26Q3-Q4 | M3: Personal Y1-Q1-Q2 (kumulativ) | O3: 27Q1-Q2 | Q3: Contractors Y1-Q3-Q4 (kumulativ) | S3: 27Q1-Q2
A4: Role | B4: Employees | C4: Cost | E4: Role | F4: FTE | G4: Cost | M4: Role | N4: Employees | O4: Cost | Q4: Role | R4: FTE | S4: Cost
A5: QA & Testing | B5: 0.75 | C5: =B5*('Role-Salary Helper '!C27*102) -> 49.725 | E5: Sr, Developer (Full-Stack) | F5: 0.5 | G5: =F5*(102*'Role-Salary Helper '!F13) -> 14280 | M5: QA & Testing | N5: 1 | O5: =N5*('Role-Salary Helper '!C27*102) -> 66.3 | Q5: Sr, Developer (Full-Stack) | R5: 1 | S5: =(R5*'Role-Salary Helper '!F13)*102 -> 28560
A6: Developer (Backend) | B6: 1 | C6: =B6*('Role-Salary Helper '!C28*102) -> 51 | E6: AI & Architecture Specialist | F6: 0.1 | G6: =F6*(102*'Role-Salary Helper '!F16) -> 3570 | M6: Developer (Backend) | N6: 2 | O6: =N6*('Role-Salary Helper '!C28*102) -> 102 | Q6: AI & Architecture Specialist | R6: 0.1 | S6: =(R6*'Role-Salary Helper '!F16)*102 -> 3570
A7: Developer (Frontend) | B7: 1 | C7: =B7*('Role-Salary Helper '!C29*102) -> 0 | E7: Ad & Contend Creator | F7: 0.1 | G7: =F7*(102*'Role-Salary Helper '!F17) -> 1530 | M7: Developer (Frontend) | N7: 1 | O7: =N7*('Role-Salary Helper '!C29*102) -> 0 | Q7: Ad & Contend Creator | R7: 0.75 | S7: =(R7*'Role-Salary Helper '!F17)*102 -> 11475
A8: UX/UI Designer | B8: 1 | C8: =B8*('Role-Salary Helper '!C30*102) -> 0 | E8: Legal | F8: 0.025 | G8: =F8*(102*'Role-Salary Helper '!F19) -> 1530 | M8: UI / UX Designer | N8: 1 | O8: =N8*('Role-Salary Helper '!C30*102) -> 0 | Q8: Sales & Acquisition | R8: N/A | S8: =(SUM('Earning Projections'!D24)*0.5)*0.05 -> 1287.5
A9: Digital Marketing | B9: 1 | C9: =B9*('Role-Salary Helper '!C16*102) -> 22440 | G9: =F9*(102*250) -> 0 | M9: Digital Marketing | N9: 1 | O9: =N9*('Role-Salary Helper '!C16*102) -> 22440 | Q9: DevOps | R9: 0.5 | S9: =R9*(102*'Role-Salary Helper '!F18) -> 15300
A10: C-Suite | B10: 2.5 | C10: =B10*(36400/2) -> 45500 | G10: =F10*(102*250) -> 0 | M10: C-Suite | N10: 3 | O10: =N10*(36400/2) -> 54600 | Q10: Legal | R10: 0.04 | S10: =R10*(102*'Role-Salary Helper '!F19) -> 2448
C11: =B11*(102*250) -> 0 | G11: =F11*(102*250) -> 0 | O11: =N11*(102*250) -> 0 | S11: =R11*(102*250) -> 0
C12: =B12*(102*250) -> 0 | G12: =F12*(102*250) -> 0 | I12: Quarter Total Cost | O12: =N12*(102*250) -> 0 | S12: =R12*(102*250) -> 0 | U12: Quarter Total Cost
A13: TOTAL | B13: =SUM(B5:B12) -> 7.25 | C13: =SUM(C5:C12) -> 68040.725 | E13: TOTAL | F13: =SUM(F5:F12) -> 0.725 | G13: =SUM(G5:G12) -> 20910 | I13: =SUM(G13,C13) -> 88950.725 | M13: TOTAL | N13: =SUM(N5:N12) -> 9 | O13: =SUM(O5:O12) -> 77208.3 | Q13: TOTAL | R13: =SUM(R5:R12) -> 2.39 | S13: =SUM(S5:S12) -> 62640.5 | U13: =SUM(S13,O13) -> 139848.8
C15: Yearly Total Cost
C16: =SUM(U13,I13) -> 228799.52
A19: Personal Y2-Q1-Q2 (kumulativ) | C19: 27Q3-Q4 | E19: Contractors Y2-Q1-Q2 (kumulativ) | G19: 27Q3-Q4 | M19: Personal Y2-Q3-Q4 (kumulativ) | O19: 28Q1-Q2 | Q19: Contractors Y2-Q3-Q4 (kumulativ) | S19: 28Q1-Q2
A20: Role | B20: Employees | C20: Cost | E20: Role | F20: FTE | G20: Cost | M20: Role | N20: Employees | O20: Cost | Q20: Role | R20: FTE | S20: Cost
A21: QA & Testing | B21: 1 | C21: =B21*('Role-Salary Helper '!C12*102) -> 19380 | E21: Sr, Developer (Full-Stack) | F21: 0.5 | G21: =F21*(102*500) -> 25500 | M21: QA & Testing | N21: 1 | O21: =N21*('Role-Salary Helper '!C12*102) -> 19380 | Q21: Sr, Developer (Full-Stack) | R21: 0.5 | S21: =R21*(102*500) -> 25500
A22: Developer (Backend) | B22: 2 | C22: =B22*('Role-Salary Helper '!C13*102) -> 48960 | E22: Ad & Contend Creator | F22: 0.75 | G22: =F22*(102*250) -> 19125 | M22: Developer (Backend) | N22: 1 | O22: =N22*('Role-Salary Helper '!C13*102) -> 24480 | Q22: AI & Architecture Specialist | R22: 0.2 | S22: =R22*(102*500) -> 10200
A23: Developer (Frontend) | B23: 1 | C23: =B23*('Role-Salary Helper '!C14*102) -> 21420 | E23: Sales & Acquisition | F23: N/A | G23: =(SUM('Earning Projections'!D25,'Earning Projections'!D26)*0.5)*0.05 -> 5635 | M23: Developer (Frontend) | N23: 1 | O23: =N23*('Role-Salary Helper '!C14*102) -> 21420 | Q23: Ad & Contend Creator | R23: 0.5 | S23: =R23*(102*250) -> 12750
A24: UX/UI Designer | B24: 1 | C24: =B24*('Role-Salary Helper '!C15*102) -> 20400 | E24: Legal | F24: 0.05 | G24: =F24*(102*'Role-Salary Helper '!F19) -> 3060 | M24: Key Account Manager | N24: 1 | O24: =N24*('Role-Salary Helper '!C17*102) -> 23970 | Q24: Sales & Acquisition | R24: N/A | S24: =(SUM('Earning Projections'!D27,'Earning Projections'!D28)*0.8)*0.05 -> 34232
A25: Digital Marketing | B25: 1 | C25: =B25*('Role-Salary Helper '!C16*102) -> 22440 | G25: =F25*(102*500) -> 0 | M25: Digital Marketing | N25: 1 | O25: =N25*('Role-Salary Helper '!C16*102) -> 22440 | Q25: Legal | R25: 0.1 | S25: =R25*(102*'Role-Salary Helper '!F19) -> 6120
A26: C-Suite | B26: 3 | C26: =B26*(36400/2) -> 54600 | G26: =F26*(102*500) -> 0 | M26: UX/UI Designer | N26: 1 | O26: =N26*('Role-Salary Helper '!C15*102) -> 20400 | S26: =R26*(102*250) -> 0
C27: =B27*(36400/2) -> 0 | G27: =F27*(102*500) -> 0 | M27: C-Suite | N27: 3 | O27: =N27*(36400/2) -> 54600 | S27: =R27*(102*250) -> 0
C28: =B28*(36400/2) -> 0 | G28: =F28*(102*500) -> 0 | I28: Quarter Total Cost | O28: =N28*(102*250) -> 0 | S28: =R28*(102*250) -> 0 | U28: Quarter Total Cost
A29: Sum Tier 2 | B29: =SUM(B21:B28) -> 9 | C29: =SUM(C21:C24) -> 110160 | E29: TOTAL | F29: =SUM(F21:F28) -> 1.3 | G29: =SUM(G21:G25) -> 53320 | I29: =SUM(G29,C29) -> 163480 | M29: TOTAL | N29: =SUM(N21:N28) -> 9 | O29: =SUM(O21:O25) -> 111690 | Q29: TOTAL | R29: =SUM(R21:R28) -> 1.3 | S29: =SUM(S21:S28) -> 88802 | U29: =SUM(S29,O29) -> 200492
C31: Yearly Total Cost
C32: =SUM(U29, I29) -> 363972
A35: Personal Y3-Q1-Q2 (kumulativ) | C35: 28Q3-Q4 | E35: Contractors Y3-Q1-Q2 (kumulativ) | G35: 28Q3-Q4 | M35: Personal Y3-Q3-Q4 (kumulativ) | O35: 29Q1-Q2 | Q35: Contractors Y1-Q3-Q4 (kumulativ) | S35: 29Q1-Q2
A36: Role | B36: Employees | C36: Cost | E36: Role | F36: FTE | G36: Cost | M36: Role | N36: Employees | O36: Cost | Q36: Role | R36: FTE | S36: Cost
A37: QA & Testing | B37: 1 | C37: =B37*('Role-Salary Helper '!C12*102) -> 19380 | E37: Sr, Developer (Full-Stack) | F37: 0.5 | G37: 25500 | M37: QA & Testing | N37: 1 | O37: =N37*('Role-Salary Helper '!C12*102) -> 19380 | Q37: Sr, Developer (Full-Stack) | R37: 0.5 | S37: =R37*(102*500) -> 25500
A38: Developer (Backend) | B38: 1 | C38: =B38*('Role-Salary Helper '!C13*102) -> 24480 | E38: Ad & Contend Creator | F38: 0.5 | G38: 12750 | M38: Developer (Backend) | N38: 1 | O38: =N38*(47500/2) -> 23750 | Q38: AI & Architecture Specialist | R38: 0.2 | S38: =R38*(102*500) -> 10200
A39: Developer (Frontend) | B39: 1 | C39: =B39*('Role-Salary Helper '!C14*102) -> 21420 | E39: Sales & Acquisition | F39: N/A | G39: =(SUM('Earning Projections'!D29,'Earning Projections'!D30)*0.5)*0.05 -> 63242.5 | M39: Developer (Frontend) | N39: 1 | O39: =N39*(47500/2) -> 23750 | Q39: Ad & Contend Creator | R39: 0.5 | S39: =R39*(102*250) -> 12750
A40: UX/UI Designer | B40: 1 | C40: =B40*('Role-Salary Helper '!C15*102) -> 20400 | E40: Legal | F40: 0.2 | G40: =F40*(102*'Role-Salary Helper '!F19) -> 12240 | M40: Digital Marketing | N40: 1 | O40: =N40*(47500/2) -> 23750 | Q40: Sales & Acquisition | R40: N/A | S40: =(SUM('Earning Projections'!D31,'Earning Projections'!D32)*0.5)*0.05 -> 145995
A41: Digital Marketing | B41: 1 | C41: =B41*('Role-Salary Helper '!C16*102) -> 22440 | G41: =F41*(102*250) -> 0 | M41: UX/UI Designer | N41: 1 | O41: =N41*(47500/2) -> 23750 | Q41: Legal | R41: 0.4 | S41: =R41*(102*'Role-Salary Helper '!F19) -> 24480
A42: Sales Development Representative | B42: 1 | C42: =B42*('Role-Salary Helper '!C18*102) -> 18360 | G42: =F42*(102*250) -> 0 | M42: Sales Development Representative | N42: 2 | O42: =N42*(50000/2) -> 50000 | S42: =R42*(102*250) -> 0
A43: Key Account Manager | B43: 1 | C43: =B43*('Role-Salary Helper '!C17*102) -> 23970 | G43: =F43*(102*250) -> 0 | M43: Key Account Manager | N43: 1 | O43: 27500 | S43: =R43*(102*250) -> 0
A44: C-Suite | B44: 3 | C44: =B44*(36400/2) -> 54600 | G44: =F44*(102*250) -> 0 | I44: Quarter Total Cost | M44: C-Suite | N44: 3 | O44: =N44*(36400/2) -> 54600 | S44: =R44*(102*250) -> 0 | U44: Quarter Total Cost
A45: TOTAL | B45: =SUM(B37:B44) -> 10 | C45: =SUM(C37:C44) -> 205050 | E45: TOTAL | F45: =SUM(F37:F44) -> 1.2 | G45: =SUM(G37:G41) -> 113732.5 | I45: =SUM(C45,G45) -> 318782.5 | M45: TOTAL | N45: =SUM(N37:N44) -> 11 | O45: =SUM(O37:O44) -> 246480 | Q45: TOTAL | R45: =SUM(R37:R44) -> 1.6 | S45: =SUM(S37:S44) -> 218925 | U45: =SUM(S45,O45) -> 465405
C47: Yearly Total Cost | G47: ! NOTE: New SDR Employees
C48: =SUM(U45, I45) -> 784187.5 | G48: will lower the relative participation Factor
G49: of External Sales Contractors
